<?xml version="1.0"?>

<robot name="ar4_robot">

    <link name="root"/>
    <joint name="root_to_base" type="fixed">
      <parent link="root"/>
      <child link="base_link"/>
      <origin rpy="0 0 3.1415926" xyz="0 0 0"/> 
    </joint>

    <link name="base_link">
      <visual>
        <geometry>
          <mesh filename="base_link.STL"/>
        </geometry>
        <material name="">
          <color rgba="1 1 1 1"/>
        </material>
      </visual>
    </link>

    <joint name="joint_1" type="revolute">
      <origin rpy="3.1415926 0 0" xyz="0 0 0.003445"/>
      <parent link="base_link"/>
      <child link="link_1"/>
      <axis xyz="0 0 -1"/>
      <limit lower="-2.96705972839036" upper="2.96705972839036" effort="0" velocity="0.5"/>
    </joint>

    <link name="link_1">
      <visual>
        <geometry>
          <mesh filename="link_1.STL"/>
        </geometry>
        <material name="">
          <color rgba="1 1 1 1"/>
        </material>
      </visual>
    </link>

    <link name="link_2">
      <visual>
        <origin rpy="0 0 0" xyz="0 0 0"/>
        <geometry>
          <mesh filename="link_2.STL"/>
        </geometry>
        <material name="">
          <color rgba="1 1 1 1"/>
        </material>
      </visual>
    </link>

    <joint name="joint_2" type="revolute">
      <origin rpy="1.5708 0.5236 -1.5708" xyz="0 0.0642 -0.16977"/>
      <parent link="link_1"/>
      <child link="link_2"/>
      <axis xyz="0 0 -1"/>
      <limit lower="-0.7330382858376184" upper="1.5707963267948966" effort="0.5" velocity="0"/>
    </joint>

    <link name="link_3">
      <visual>
        <origin rpy="0 0 0" xyz="0 0 0"/>
        <geometry>
          <mesh filename="link_3.STL"/>
        </geometry>
        <material name="">
          <color rgba="1 1 1 1"/>
        </material>
      </visual>
    </link>

    <joint name="joint_3" type="revolute">
      <origin rpy="0 0 -2.61799" xyz="0.1525 -0.26414 0"/>
      <parent link="link_2"/>
      <child link="link_3"/>
      <axis xyz="0 0 -1"/>
      <limit lower="-1.5533430342749532" upper="0.9075712110370513" effort="0" velocity="0.5"/>
    </joint>

    <link name="link_4">
      <visual>
        <origin rpy="0 0 0" xyz="0 0 0"/>
        <geometry>
          <mesh filename="link_4.STL"/>
        </geometry>
        <material name="">
          <color rgba="1 1 1 1"/>
        </material>
      </visual>
    </link>

    <joint name="joint_4" type="revolute">
      <origin rpy="1.5708 -1.2554 -1.5708" xyz="0 0 0"/>
      <parent link="link_3"/>
      <child link="link_4"/>
      <axis xyz="0 0 -1"/>
      <limit lower="-2.8797932657906435" upper="2.8797932657906435" effort="0" velocity="0.5"/>
    </joint>

    <link name="link_5">
      <visual>
        <origin rpy="0 0 0" xyz="0 0 0"/>
        <geometry>
          <mesh filename="link_5.STL"/>
        </geometry>
        <material name="">
          <color rgba="1 1 1 1"/>
        </material>
      </visual>
    </link>

    <joint name="joint_5" type="revolute">
      <origin rpy="3.1415926 0 -2.8262" xyz="0 0 -0.22225"/>
      <parent link="link_4"/>
      <child link="link_5"/>
      <axis xyz="1 0 0"/>
      <limit lower="-1.8325957145940461" upper="1.8325957145940461" effort="0" velocity="0.5"/>
    </joint>

    <link name="link_6">
      <visual>
        <origin rpy="0 0 0" xyz="0 0 0"/>
        <geometry>
          <mesh filename="link_6.STL"/>
        </geometry>
        <material name="">
          <color rgba="1 1 1 1"/>
        </material>
      </visual>
    </link>
    
    <joint name="joint_6" type="revolute">
      <origin rpy="0 0 3.1416" xyz="0 0 0.02117"/>
      <parent link="link_5"/>
      <child link="link_6"/>
      <axis xyz="0 0 1"/>
      <limit lower="-2.705260340591211" upper="2.705260340591211" effort="0" velocity="0.5"/>
    </joint>

  <joint name="ee_joint" type="fixed">
    <origin rpy="0 0 -1.5708" xyz="0 0 0.016"/>
    <parent link="link_6"/>
    <child link="ee_link"/>
  </joint>
  
  <link name="ee_link"/>

</robot>

